Workbook
Name mkt_brokers: Assumptions!$C$6
Name mkt_brokers_high: Assumptions!$C$7
Name mkt_carriers: Assumptions!$C$8
Name mkt_carriers_ds: Assumptions!$C$9
Name mkt_overlap: Assumptions!$C$10
Name mkt_case: Assumptions!$C$11
Name addressable: Assumptions!$C$12
Name pen_low: Assumptions!$C$13
Name pen_base: Assumptions!$C$14
Name pen_high: Assumptions!$C$15
Name ramp_exp: Assumptions!$C$16
Name start_tenants: Assumptions!$C$17
Name churn_m: Assumptions!$C$18
Name p_platform: Assumptions!$C$21
Name p_dialer: Assumptions!$C$22
Name incl_min: Assumptions!$C$23
Name over_mult: Assumptions!$C$24
Name bill_over: Assumptions!$C$25
Name p_sms: Assumptions!$C$26
Name incl_seg: Assumptions!$C$27
Name sms_setup: Assumptions!$C$28
Name p_comp: Assumptions!$C$29
Name p_ai: Assumptions!$C$30
Name p_onboard: Assumptions!$C$31
Name bundle_disc: Assumptions!$C$32
Name att_dialer: Assumptions!$C$33
Name att_sms: Assumptions!$C$34
Name att_comp: Assumptions!$C$35
Name att_ai: Assumptions!$C$36
Name zoho_margin: Assumptions!$C$37
Name target_gm: Assumptions!$C$38
Name seats: Assumptions!$C$41
Name nums_per_seat: Assumptions!$C$42
Name nums_shared: Assumptions!$C$43
Name leads_per_seat: Assumptions!$C$44
Name d_leads: Assumptions!$C$45
Name workdays: Assumptions!$C$48
Name att_day: Assumptions!$C$49
Name sh_person: Assumptions!$C$50
Name sh_vm: Assumptions!$C$51
Name sh_unans: Assumptions!$C$52
Name min_person: Assumptions!$C$53
Name min_vm: Assumptions!$C$54
Name min_ring: Assumptions!$C$55
Name in_day: Assumptions!$C$56
Name in_ans: Assumptions!$C$57
Name min_in: Assumptions!$C$58
Name min_in_unans: Assumptions!$C$59
Name rec_out: Assumptions!$C$60
Name rec_in: Assumptions!$C$61
Name retention: Assumptions!$C$62
Name amd_on: Assumptions!$C$63
Name band: Assumptions!$C$64
Name d_attempts: Assumptions!$C$65
Name d_out_min: Assumptions!$C$66
Name d_in_calls: Assumptions!$C$67
Name d_in_min: Assumptions!$C$68
Name d_browser_min: Assumptions!$C$69
Name d_rec_min: Assumptions!$C$70
Name d_calls: Assumptions!$C$71

Sheet Assumptions
A1: HaulOS pricing model: assumptions
A2: Blue is an input. Black is a formula. Every input carries a source and a confidence. ASSUMPTION means nobody has measured it.
A4: Key | B4: Input | C4: Value | D4: Unit | E4: Source | F4: Confidence | G4: Note
A5: Market
A6: mkt_brokers | B6: Active household-goods broker authorities | C6: 901 | D6: firms | E6: FMCSA dataset 6eyk-hxee on data.transportation.gov, counted 2026-10-04: broker_stat='A' AND hhg_chk='Y' | F6: Med | G6: The count is exact. What the household-goods flag means is not fully confirmed.
A7: mkt_brokers_high | B7: Broker count, high case | C7: 1256 | D7: firms | E7: FMCSA 2024 notice, as given in the brief; not re-read | F7: Med
A8: mkt_carriers | B8: Household-goods carriers | C8: 4000 | D8: firms | E8: Figure given in the brief ("roughly 4,000", older) | F8: Low | G8: The dataset counts 8,596 active carrier authorities with the flag: see the next row.
A9: mkt_carriers_ds | B9: Carrier count, dataset upper bound | C9: 8596 | D9: firms | E9: FMCSA dataset 6eyk-hxee on data.transportation.gov, counted 2026-10-04: hhg_chk='Y' AND (common_stat='A' OR contract_stat='A') | F9: Low | G9: An authority that covers household goods, not proof the firm moves households.
A10: mkt_overlap | B10: Firms that are both broker and carrier | C10: 237 | D10: firms | E10: FMCSA dataset 6eyk-hxee on data.transportation.gov, counted 2026-10-04 | F10: Med
A11: mkt_case | B11: Market case: 1 brokers, 2 brokers high, 3 brokers + carriers, 4 brokers + carriers (dataset) | C11: 1 | D11: switch | E11: Choice | F11: ASSUMPTION
A12: addressable | B12: Addressable firms, selected case | C12: =CHOOSE($C$11,$C$6,$C$7,$C$6+$C$8-$C$10,$C$6+$C$9-$C$10) | D12: firms | E12: Formula
A13: pen_low | B13: Share of addressable firms at month 24, low | C13: 0.02 | D13: % | E13: Starting hypothesis in the brief | F13: ASSUMPTION
A14: pen_base | B14: Share of addressable firms at month 24, base | C14: 0.05 | D14: % | E14: Starting hypothesis in the brief | F14: ASSUMPTION
A15: pen_high | B15: Share of addressable firms at month 24, high | C15: 0.1 | D15: % | E15: Starting hypothesis in the brief | F15: ASSUMPTION
A16: ramp_exp | B16: Ramp shape | C16: 1.5 | D16: exponent | E16: Nothing measured | F16: ASSUMPTION | G16: 1 is a straight line to month 24. Higher starts slower.
A17: start_tenants | B17: Tenants today | C17: 1 | D17: tenants | E17: The first client is live | F17: High
A18: churn_m | B18: Tenants lost per month | C18: 0.015 | D18: % | E18: Nothing measured | F18: ASSUMPTION | G18: Only changes how many new tenants are needed, and so the one-time fees.
A20: Prices
A21: p_platform | B21: Platform fee | C21: 349 | D21: $ / tenant / month | E21: Starting hypothesis in the brief (test $299 to $499) | F21: ASSUMPTION
A22: p_dialer | B22: Dialer add-on | C22: 79 | D22: $ / seat / month | E22: Starting hypothesis in the brief | F22: ASSUMPTION
A23: incl_min | B23: Minutes included with a dialer seat | C23: 1200 | D23: minutes / seat / month | E23: Starting hypothesis in the brief | F23: ASSUMPTION | G23: Counted as phone minutes, outbound plus inbound.
A24: over_mult | B24: Overage price as a multiple of cost | C24: 2.5 | D24: x | E24: Starting hypothesis in the brief | F24: ASSUMPTION
A25: bill_over | B25: Overage is charged: 1 yes, 0 no | C25: 1 | D25: switch | E25: Choice | F25: ASSUMPTION
A26: p_sms | B26: SMS add-on | C26: 49 | D26: $ / tenant / month | E26: Starting hypothesis in the brief | F26: ASSUMPTION
A27: incl_seg | B27: Segments included with the SMS add-on | C27: 1000 | D27: segments / month | E27: Starting hypothesis in the brief | F27: ASSUMPTION | G27: Outbound segments.
A28: sms_setup | B28: SMS setup fee | C28: 399 | D28: $ one-time | E28: Starting hypothesis in the brief | F28: ASSUMPTION
A29: p_comp | B29: Compliance module | C29: 79 | D29: $ / tenant / month | E29: Starting hypothesis in the brief | F29: ASSUMPTION
A30: p_ai | B30: AI SMS add-on | C30: 249 | D30: $ / tenant / month | E30: Starting hypothesis in the brief (a test price) | F30: ASSUMPTION
A31: p_onboard | B31: Platform setup fee | C31: 0 | D31: $ one-time | E31: Not in the brief | F31: ASSUMPTION | G31: Set above zero to model a setup fee.
A32: bundle_disc | B32: Discount on a bundle | C32: 0 | D32: % | E32: Not in the brief | F32: ASSUMPTION
A33: att_dialer | B33: Tenants that take the dialer | C33: 0.6 | D33: % | E33: Starting hypothesis in the brief | F33: ASSUMPTION
A34: att_sms | B34: Tenants that take SMS | C34: 0.5 | D34: % | E34: Starting hypothesis in the brief | F34: ASSUMPTION
A35: att_comp | B35: Tenants that take compliance | C35: 0.4 | D35: % | E35: Starting hypothesis in the brief | F35: ASSUMPTION
A36: att_ai | B36: Tenants that take AI SMS | C36: 0.2 | D36: % | E36: Starting hypothesis in the brief | F36: ASSUMPTION
A37: zoho_margin | B37: Kore margin on Zoho licenses | C37: 0 | D37: % | E37: Partner application in progress. Zoho publishes no reseller margin | F37: ASSUMPTION | G37: One third-party page says 15% to 25% (Low confidence).
A38: target_gm | B38: Gross-margin target | C38: 0.7 | D38: % | E38: Nothing measured | F38: ASSUMPTION | G38: Used only for the breakeven lines.
A40: Tenant shape
A41: seats | B41: Seats per tenant | C41: 4 | D41: seats | E41: Starting hypothesis in the brief | F41: ASSUMPTION | G41: The first client has 2 Zoho Voice users (seen 2026-09-30).
A42: nums_per_seat | B42: Phone numbers per seat | C42: 1 | D42: numbers | E42: Nothing measured | F42: ASSUMPTION | G42: A direct line per rep.
A43: nums_shared | B43: Shared phone numbers per tenant | C43: 1 | D43: numbers | E43: Nothing measured | F43: ASSUMPTION | G43: The main line.
...

Sheet UsageActuals
A1: Usage actuals
A2: From inputs/usage-actuals.json, pulled 2026-10-05T02:27:33Z, window 2026-07-01 to 2026-10-04. A blank cell is a null: not retrieved, not zero.
A4: Include = 1 counts the row in the per-seat figures. Development, sandbox and part-months start at 0. Set a ramp-up month to 0 to leave it out.
E5: voice | F5: voice | G5: voice | H5: voice | I5: voice | J5: voice | K5: voice | L5: voice | M5: voice | N5: voice | O5: voice | P5: voice | Q5: voice | R5: voice | S5: sms | T5: sms | U5: sms | V5: sms | W5: sms | X5: sms | Y5: sms | Z5: sms | AA5: zoho_crm | AB5: zoho_crm | AC5: zoho_crm | AD5: zoho_crm | AE5: zoho_crm | AF5: zoho_crm | AG5: zoho_marketing | AI5: derived | AJ5: derived | AK5: derived | AL5: derived | AM5: derived | AN5: derived | AO5: derived | AP5: derived | AQ5: derived
A6: Tenant | B6: Environment | C6: Month | D6: Include | E6: calls_out | F6: calls_in | G6: connected_calls | H6: avg_duration_sec | I6: median_duration_sec | J6: billed_min_total | K6: billed_min_pstn_out | L6: billed_min_pstn_in | M6: billed_min_browser_leg | N6: recorded_min | O6: voicemail_drops | P6: amd_calls | Q6: active_agents | R6: peak_concurrent | S6: msgs_out | T6: msgs_in | U6: segments_out | V6: segments_in | W6: delivery_rate | X6: opt_outs | Y6: filtered_errors | Z6: carrier_fee_usd | AA6: licensed_users | AB6: edition | AC6: api_credits_per_day_avg | AD6: api_credits_per_day_peak | AE6: api_credit_limit | AF6: call_records_created | AG6: sends | AI6: Billed minutes, PSTN outbound, per seat / month | AJ6: Billed minutes, PSTN inbound, per seat / month | AK6: Billed minutes, browser leg, per seat / month | AL6: Recorded minutes, per seat / month | AM6: Calls, out plus in, per seat / month | AN6: Answering-machine-detection calls, per seat / month | AO6: Outbound SMS segments, per seat / month | AP6: Inbound SMS segments, per seat / month | AQ6: AI conversations, per tenant / month
A7: kore | B7: dev | C7: 2026-07 | D7: 0 | AI7: =IF(AND($D7=1,ISNUMBER(K7),ISNUMBER(Q7)),IF(Q7>0,(K7)/Q7,""),"") | AJ7: =IF(AND($D7=1,ISNUMBER(L7),ISNUMBER(Q7)),IF(Q7>0,(L7)/Q7,""),"") | AK7: =IF(AND($D7=1,ISNUMBER(M7),ISNUMBER(Q7)),IF(Q7>0,(M7)/Q7,""),"") | AL7: =IF(AND($D7=1,ISNUMBER(N7),ISNUMBER(Q7)),IF(Q7>0,(N7)/Q7,""),"") | AM7: =IF(AND($D7=1,ISNUMBER(E7),ISNUMBER(F7),ISNUMBER(Q7)),IF(Q7>0,(E7+F7)/Q7,""),"") | AN7: =IF(AND($D7=1,ISNUMBER(P7),ISNUMBER(Q7)),IF(Q7>0,(P7)/Q7,""),"") | AO7: =IF(AND($D7=1,ISNUMBER(U7),ISNUMBER(Q7)),IF(Q7>0,(U7)/Q7,""),"") | AP7: =IF(AND($D7=1,ISNUMBER(V7),ISNUMBER(Q7)),IF(Q7>0,(V7)/Q7,""),"")
A8: kore | B8: dev | C8: 2026-08 | D8: 0 | AI8: =IF(AND($D8=1,ISNUMBER(K8),ISNUMBER(Q8)),IF(Q8>0,(K8)/Q8,""),"") | AJ8: =IF(AND($D8=1,ISNUMBER(L8),ISNUMBER(Q8)),IF(Q8>0,(L8)/Q8,""),"") | AK8: =IF(AND($D8=1,ISNUMBER(M8),ISNUMBER(Q8)),IF(Q8>0,(M8)/Q8,""),"") | AL8: =IF(AND($D8=1,ISNUMBER(N8),ISNUMBER(Q8)),IF(Q8>0,(N8)/Q8,""),"") | AM8: =IF(AND($D8=1,ISNUMBER(E8),ISNUMBER(F8),ISNUMBER(Q8)),IF(Q8>0,(E8+F8)/Q8,""),"") | AN8: =IF(AND($D8=1,ISNUMBER(P8),ISNUMBER(Q8)),IF(Q8>0,(P8)/Q8,""),"") | AO8: =IF(AND($D8=1,ISNUMBER(U8),ISNUMBER(Q8)),IF(Q8>0,(U8)/Q8,""),"") | AP8: =IF(AND($D8=1,ISNUMBER(V8),ISNUMBER(Q8)),IF(Q8>0,(V8)/Q8,""),"")
A9: kore | B9: dev | C9: 2026-09 | D9: 0 | AI9: =IF(AND($D9=1,ISNUMBER(K9),ISNUMBER(Q9)),IF(Q9>0,(K9)/Q9,""),"") | AJ9: =IF(AND($D9=1,ISNUMBER(L9),ISNUMBER(Q9)),IF(Q9>0,(L9)/Q9,""),"") | AK9: =IF(AND($D9=1,ISNUMBER(M9),ISNUMBER(Q9)),IF(Q9>0,(M9)/Q9,""),"") | AL9: =IF(AND($D9=1,ISNUMBER(N9),ISNUMBER(Q9)),IF(Q9>0,(N9)/Q9,""),"") | AM9: =IF(AND($D9=1,ISNUMBER(E9),ISNUMBER(F9),ISNUMBER(Q9)),IF(Q9>0,(E9+F9)/Q9,""),"") | AN9: =IF(AND($D9=1,ISNUMBER(P9),ISNUMBER(Q9)),IF(Q9>0,(P9)/Q9,""),"") | AO9: =IF(AND($D9=1,ISNUMBER(U9),ISNUMBER(Q9)),IF(Q9>0,(U9)/Q9,""),"") | AP9: =IF(AND($D9=1,ISNUMBER(V9),ISNUMBER(Q9)),IF(Q9>0,(V9)/Q9,""),"")
A10: kore | B10: dev | C10: 2026-10 | D10: 0 | AI10: =IF(AND($D10=1,ISNUMBER(K10),ISNUMBER(Q10)),IF(Q10>0,(K10)/Q10,""),"") | AJ10: =IF(AND($D10=1,ISNUMBER(L10),ISNUMBER(Q10)),IF(Q10>0,(L10)/Q10,""),"") | AK10: =IF(AND($D10=1,ISNUMBER(M10),ISNUMBER(Q10)),IF(Q10>0,(M10)/Q10,""),"") | AL10: =IF(AND($D10=1,ISNUMBER(N10),ISNUMBER(Q10)),IF(Q10>0,(N10)/Q10,""),"") | AM10: =IF(AND($D10=1,ISNUMBER(E10),ISNUMBER(F10),ISNUMBER(Q10)),IF(Q10>0,(E10+F10)/Q10,""),"") | AN10: =IF(AND($D10=1,ISNUMBER(P10),ISNUMBER(Q10)),IF(Q10>0,(P10)/Q10,""),"") | AO10: =IF(AND($D10=1,ISNUMBER(U10),ISNUMBER(Q10)),IF(Q10>0,(U10)/Q10,""),"") | AP10: =IF(AND($D10=1,ISNUMBER(V10),ISNUMBER(Q10)),IF(Q10>0,(V10)/Q10,""),"")
A11: kore-sandbox | B11: sandbox | C11: 2026-07 | D11: 0 | AI11: =IF(AND($D11=1,ISNUMBER(K11),ISNUMBER(Q11)),IF(Q11>0,(K11)/Q11,""),"") | AJ11: =IF(AND($D11=1,ISNUMBER(L11),ISNUMBER(Q11)),IF(Q11>0,(L11)/Q11,""),"") | AK11: =IF(AND($D11=1,ISNUMBER(M11),ISNUMBER(Q11)),IF(Q11>0,(M11)/Q11,""),"") | AL11: =IF(AND($D11=1,ISNUMBER(N11),ISNUMBER(Q11)),IF(Q11>0,(N11)/Q11,""),"") | AM11: =IF(AND($D11=1,ISNUMBER(E11),ISNUMBER(F11),ISNUMBER(Q11)),IF(Q11>0,(E11+F11)/Q11,""),"") | AN11: =IF(AND($D11=1,ISNUMBER(P11),ISNUMBER(Q11)),IF(Q11>0,(P11)/Q11,""),"") | AO11: =IF(AND($D11=1,ISNUMBER(U11),ISNUMBER(Q11)),IF(Q11>0,(U11)/Q11,""),"") | AP11: =IF(AND($D11=1,ISNUMBER(V11),ISNUMBER(Q11)),IF(Q11>0,(V11)/Q11,""),"")
A12: kore-sandbox | B12: sandbox | C12: 2026-08 | D12: 0 | AI12: =IF(AND($D12=1,ISNUMBER(K12),ISNUMBER(Q12)),IF(Q12>0,(K12)/Q12,""),"") | AJ12: =IF(AND($D12=1,ISNUMBER(L12),ISNUMBER(Q12)),IF(Q12>0,(L12)/Q12,""),"") | AK12: =IF(AND($D12=1,ISNUMBER(M12),ISNUMBER(Q12)),IF(Q12>0,(M12)/Q12,""),"") | AL12: =IF(AND($D12=1,ISNUMBER(N12),ISNUMBER(Q12)),IF(Q12>0,(N12)/Q12,""),"") | AM12: =IF(AND($D12=1,ISNUMBER(E12),ISNUMBER(F12),ISNUMBER(Q12)),IF(Q12>0,(E12+F12)/Q12,""),"") | AN12: =IF(AND($D12=1,ISNUMBER(P12),ISNUMBER(Q12)),IF(Q12>0,(P12)/Q12,""),"") | AO12: =IF(AND($D12=1,ISNUMBER(U12),ISNUMBER(Q12)),IF(Q12>0,(U12)/Q12,""),"") | AP12: =IF(AND($D12=1,ISNUMBER(V12),ISNUMBER(Q12)),IF(Q12>0,(V12)/Q12,""),"")
A13: kore-sandbox | B13: sandbox | C13: 2026-09 | D13: 0 | AI13: =IF(AND($D13=1,ISNUMBER(K13),ISNUMBER(Q13)),IF(Q13>0,(K13)/Q13,""),"") | AJ13: =IF(AND($D13=1,ISNUMBER(L13),ISNUMBER(Q13)),IF(Q13>0,(L13)/Q13,""),"") | AK13: =IF(AND($D13=1,ISNUMBER(M13),ISNUMBER(Q13)),IF(Q13>0,(M13)/Q13,""),"") | AL13: =IF(AND($D13=1,ISNUMBER(N13),ISNUMBER(Q13)),IF(Q13>0,(N13)/Q13,""),"") | AM13: =IF(AND($D13=1,ISNUMBER(E13),ISNUMBER(F13),ISNUMBER(Q13)),IF(Q13>0,(E13+F13)/Q13,""),"") | AN13: =IF(AND($D13=1,ISNUMBER(P13),ISNUMBER(Q13)),IF(Q13>0,(P13)/Q13,""),"") | AO13: =IF(AND($D13=1,ISNUMBER(U13),ISNUMBER(Q13)),IF(Q13>0,(U13)/Q13,""),"") | AP13: =IF(AND($D13=1,ISNUMBER(V13),ISNUMBER(Q13)),IF(Q13>0,(V13)/Q13,""),"")
A14: kore-sandbox | B14: sandbox | C14: 2026-10 | D14: 0 | AI14: =IF(AND($D14=1,ISNUMBER(K14),ISNUMBER(Q14)),IF(Q14>0,(K14)/Q14,""),"") | AJ14: =IF(AND($D14=1,ISNUMBER(L14),ISNUMBER(Q14)),IF(Q14>0,(L14)/Q14,""),"") | AK14: =IF(AND($D14=1,ISNUMBER(M14),ISNUMBER(Q14)),IF(Q14>0,(M14)/Q14,""),"") | AL14: =IF(AND($D14=1,ISNUMBER(N14),ISNUMBER(Q14)),IF(Q14>0,(N14)/Q14,""),"") | AM14: =IF(AND($D14=1,ISNUMBER(E14),ISNUMBER(F14),ISNUMBER(Q14)),IF(Q14>0,(E14+F14)/Q14,""),"") | AN14: =IF(AND($D14=1,ISNUMBER(P14),ISNUMBER(Q14)),IF(Q14>0,(P14)/Q14,""),"") | AO14: =IF(AND($D14=1,ISNUMBER(U14),ISNUMBER(Q14)),IF(Q14>0,(U14)/Q14,""),"") | AP14: =IF(AND($D14=1,ISNUMBER(V14),ISNUMBER(Q14)),IF(Q14>0,(V14)/Q14,""),"")
A15: the-moving-group | B15: prod | C15: 2026-07 | D15: 1 | AI15: =IF(AND($D15=1,ISNUMBER(K15),ISNUMBER(Q15)),IF(Q15>0,(K15)/Q15,""),"") | AJ15: =IF(AND($D15=1,ISNUMBER(L15),ISNUMBER(Q15)),IF(Q15>0,(L15)/Q15,""),"") | AK15: =IF(AND($D15=1,ISNUMBER(M15),ISNUMBER(Q15)),IF(Q15>0,(M15)/Q15,""),"") | AL15: =IF(AND($D15=1,ISNUMBER(N15),ISNUMBER(Q15)),IF(Q15>0,(N15)/Q15,""),"") | AM15: =IF(AND($D15=1,ISNUMBER(E15),ISNUMBER(F15),ISNUMBER(Q15)),IF(Q15>0,(E15+F15)/Q15,""),"") | AN15: =IF(AND($D15=1,ISNUMBER(P15),ISNUMBER(Q15)),IF(Q15>0,(P15)/Q15,""),"") | AO15: =IF(AND($D15=1,ISNUMBER(U15),ISNUMBER(Q15)),IF(Q15>0,(U15)/Q15,""),"") | AP15: =IF(AND($D15=1,ISNUMBER(V15),ISNUMBER(Q15)),IF(Q15>0,(V15)/Q15,""),"")
A16: the-moving-group | B16: prod | C16: 2026-08 | D16: 1 | AI16: =IF(AND($D16=1,ISNUMBER(K16),ISNUMBER(Q16)),IF(Q16>0,(K16)/Q16,""),"") | AJ16: =IF(AND($D16=1,ISNUMBER(L16),ISNUMBER(Q16)),IF(Q16>0,(L16)/Q16,""),"") | AK16: =IF(AND($D16=1,ISNUMBER(M16),ISNUMBER(Q16)),IF(Q16>0,(M16)/Q16,""),"") | AL16: =IF(AND($D16=1,ISNUMBER(N16),ISNUMBER(Q16)),IF(Q16>0,(N16)/Q16,""),"") | AM16: =IF(AND($D16=1,ISNUMBER(E16),ISNUMBER(F16),ISNUMBER(Q16)),IF(Q16>0,(E16+F16)/Q16,""),"") | AN16: =IF(AND($D16=1,ISNUMBER(P16),ISNUMBER(Q16)),IF(Q16>0,(P16)/Q16,""),"") | AO16: =IF(AND($D16=1,ISNUMBER(U16),ISNUMBER(Q16)),IF(Q16>0,(U16)/Q16,""),"") | AP16: =IF(AND($D16=1,ISNUMBER(V16),ISNUMBER(Q16)),IF(Q16>0,(V16)/Q16,""),"")
A17: the-moving-group | B17: prod | C17: 2026-09 | D17: 1 | AI17: =IF(AND($D17=1,ISNUMBER(K17),ISNUMBER(Q17)),IF(Q17>0,(K17)/Q17,""),"") | AJ17: =IF(AND($D17=1,ISNUMBER(L17),ISNUMBER(Q17)),IF(Q17>0,(L17)/Q17,""),"") | AK17: =IF(AND($D17=1,ISNUMBER(M17),ISNUMBER(Q17)),IF(Q17>0,(M17)/Q17,""),"") | AL17: =IF(AND($D17=1,ISNUMBER(N17),ISNUMBER(Q17)),IF(Q17>0,(N17)/Q17,""),"") | AM17: =IF(AND($D17=1,ISNUMBER(E17),ISNUMBER(F17),ISNUMBER(Q17)),IF(Q17>0,(E17+F17)/Q17,""),"") | AN17: =IF(AND($D17=1,ISNUMBER(P17),ISNUMBER(Q17)),IF(Q17>0,(P17)/Q17,""),"") | AO17: =IF(AND($D17=1,ISNUMBER(U17),ISNUMBER(Q17)),IF(Q17>0,(U17)/Q17,""),"") | AP17: =IF(AND($D17=1,ISNUMBER(V17),ISNUMBER(Q17)),IF(Q17>0,(V17)/Q17,""),"")
A18: the-moving-group | B18: prod | C18: 2026-10 | D18: 0 | AI18: =IF(AND($D18=1,ISNUMBER(K18),ISNUMBER(Q18)),IF(Q18>0,(K18)/Q18,""),"") | AJ18: =IF(AND($D18=1,ISNUMBER(L18),ISNUMBER(Q18)),IF(Q18>0,(L18)/Q18,""),"") | AK18: =IF(AND($D18=1,ISNUMBER(M18),ISNUMBER(Q18)),IF(Q18>0,(M18)/Q18,""),"") | AL18: =IF(AND($D18=1,ISNUMBER(N18),ISNUMBER(Q18)),IF(Q18>0,(N18)/Q18,""),"") | AM18: =IF(AND($D18=1,ISNUMBER(E18),ISNUMBER(F18),ISNUMBER(Q18)),IF(Q18>0,(E18+F18)/Q18,""),"") | AN18: =IF(AND($D18=1,ISNUMBER(P18),ISNUMBER(Q18)),IF(Q18>0,(P18)/Q18,""),"") | AO18: =IF(AND($D18=1,ISNUMBER(U18),ISNUMBER(Q18)),IF(Q18>0,(U18)/Q18,""),"") | AP18: =IF(AND($D18=1,ISNUMBER(V18),ISNUMBER(Q18)),IF(Q18>0,(V18)/Q18,""),"")
A21: Usage profile: measured where there is data, assumed where there is not
A22: Metric | B22: Unit | C22: n (months) | D22: Mean | E22: Median | F22: P25 | G22: P90 | H22: Assumption | I22: Low used | J22: Base used | K22: High used | L22: Basis
A23: Billed minutes, PSTN outbound | B23: per seat / month | C23: =COUNT($AI$7:$AI$18) | D23: =IF(C23=0,"",AVERAGE($AI$7:$AI$18)) | E23: =IF(C23=0,"",MEDIAN($AI$7:$AI$18)) | F23: =IF(C23=0,"",PERCENTILE($AI$7:$AI$18,0.25)) | G23: =IF(C23=0,"",PERCENTILE($AI$7:$AI$18,0.9)) | H23: =Assumptions!$C$66 | I23: =IF(C23>=3,F23,J23*(1-Assumptions!$C$64)) | J23: =IF(C23=0,H23,D23) | K23: =IF(C23>=3,G23,J23*(1+Assumptions!$C$64)) | L23: =IF(C23=0,"ASSUMPTION",IF(C23<3,"Actual mean, banded","Actual P25 / mean / P90"))
A24: Billed minutes, PSTN inbound | B24: per seat / month | C24: =COUNT($AJ$7:$AJ$18) | D24: =IF(C24=0,"",AVERAGE($AJ$7:$AJ$18)) | E24: =IF(C24=0,"",MEDIAN($AJ$7:$AJ$18)) | F24: =IF(C24=0,"",PERCENTILE($AJ$7:$AJ$18,0.25)) | G24: =IF(C24=0,"",PERCENTILE($AJ$7:$AJ$18,0.9)) | H24: =Assumptions!$C$68 | I24: =IF(C24>=3,F24,J24*(1-Assumptions!$C$64)) | J24: =IF(C24=0,H24,D24) | K24: =IF(C24>=3,G24,J24*(1+Assumptions!$C$64)) | L24: =IF(C24=0,"ASSUMPTION",IF(C24<3,"Actual mean, banded","Actual P25 / mean / P90"))
A25: Billed minutes, browser leg | B25: per seat / month | C25: =COUNT($AK$7:$AK$18) | D25: =IF(C25=0,"",AVERAGE($AK$7:$AK$18)) | E25: =IF(C25=0,"",MEDIAN($AK$7:$AK$18)) | F25: =IF(C25=0,"",PERCENTILE($AK$7:$AK$18,0.25)) | G25: =IF(C25=0,"",PERCENTILE($AK$7:$AK$18,0.9)) | H25: =Assumptions!$C$69 | I25: =IF(C25>=3,F25,J25*(1-Assumptions!$C$64)) | J25: =IF(C25=0,H25,D25) | K25: =IF(C25>=3,G25,J25*(1+Assumptions!$C$64)) | L25: =IF(C25=0,"ASSUMPTION",IF(C25<3,"Actual mean, banded","Actual P25 / mean / P90"))
A26: Recorded minutes | B26: per seat / month | C26: =COUNT($AL$7:$AL$18) | D26: =IF(C26=0,"",AVERAGE($AL$7:$AL$18)) | E26: =IF(C26=0,"",MEDIAN($AL$7:$AL$18)) | F26: =IF(C26=0,"",PERCENTILE($AL$7:$AL$18,0.25)) | G26: =IF(C26=0,"",PERCENTILE($AL$7:$AL$18,0.9)) | H26: =Assumptions!$C$70 | I26: =IF(C26>=3,F26,J26*(1-Assumptions!$C$64)) | J26: =IF(C26=0,H26,D26) | K26: =IF(C26>=3,G26,J26*(1+Assumptions!$C$64)) | L26: =IF(C26=0,"ASSUMPTION",IF(C26<3,"Actual mean, banded","Actual P25 / mean / P90"))
A27: Calls, out plus in | B27: per seat / month | C27: =COUNT($AM$7:$AM$18) | D27: =IF(C27=0,"",AVERAGE($AM$7:$AM$18)) | E27: =IF(C27=0,"",MEDIAN($AM$7:$AM$18)) | F27: =IF(C27=0,"",PERCENTILE($AM$7:$AM$18,0.25)) | G27: =IF(C27=0,"",PERCENTILE($AM$7:$AM$18,0.9)) | H27: =Assumptions!$C$71 | I27: =IF(C27>=3,F27,J27*(1-Assumptions!$C$64)) | J27: =IF(C27=0,H27,D27) | K27: =IF(C27>=3,G27,J27*(1+Assumptions!$C$64)) | L27: =IF(C27=0,"ASSUMPTION",IF(C27<3,"Actual mean, banded","Actual P25 / mean / P90"))
A28: Answering-machine-detection calls | B28: per seat / month | C28: =COUNT($AN$7:$AN$18) | D28: =IF(C28=0,"",AVERAGE($AN$7:$AN$18)) | E28: =IF(C28=0,"",MEDIAN($AN$7:$AN$18)) | F28: =IF(C28=0,"",PERCENTILE($AN$7:$AN$18,0.25)) | G28: =IF(C28=0,"",PERCENTILE($AN$7:$AN$18,0.9)) | H28: =Assumptions!$C$72 | I28: =IF(C28>=3,F28,J28*(1-Assumptions!$C$64)) | J28: =IF(C28=0,H28,D28) | K28: =IF(C28>=3,G28,J28*(1+Assumptions!$C$64)) | L28: =IF(C28=0,"ASSUMPTION",IF(C28<3,"Actual mean, banded","Actual P25 / mean / P90"))
A29: Outbound SMS segments | B29: per seat / month | C29: =COUNT($AO$7:$AO$18) | D29: =IF(C29=0,"",AVERAGE($AO$7:$AO$18)) | E29: =IF(C29=0,"",MEDIAN($AO$7:$AO$18)) | F29: =IF(C29=0,"",PERCENTILE($AO$7:$AO$18,0.25)) | G29: =IF(C29=0,"",PERCENTILE($AO$7:$AO$18,0.9)) | H29: =Assumptions!$C$81 | I29: =IF(C29>=3,F29,J29*(1-Assumptions!$C$64)) | J29: =IF(C29=0,H29,D29) | K29: =IF(C29>=3,G29,J29*(1+Assumptions!$C$64)) | L29: =IF(C29=0,"ASSUMPTION",IF(C29<3,"Actual mean, banded","Actual P25 / mean / P90"))
A30: Inbound SMS segments | B30: per seat / month | C30: =COUNT($AP$7:$AP$18) | D30: =IF(C30=0,"",AVERAGE($AP$7:$AP$18)) | E30: =IF(C30=0,"",MEDIAN($AP$7:$AP$18)) | F30: =IF(C30=0,"",PERCENTILE($AP$7:$AP$18,0.25)) | G30: =IF(C30=0,"",PERCENTILE($AP$7:$AP$18,0.9)) | H30: =Assumptions!$C$82 | I30: =IF(C30>=3,F30,J30*(1-Assumptions!$C$64)) | J30: =IF(C30=0,H30,D30) | K30: =IF(C30>=3,G30,J30*(1+Assumptions!$C$64)) | L30: =IF(C30=0,"ASSUMPTION",IF(C30<3,"Actual mean, banded","Actual P25 / mean / P90"))
A31: AI conversations | B31: per tenant / month | C31: 0 | H31: =Assumptions!$C$90 | I31: =IF(C31>=3,F31,J31*(1-Assumptions!$C$64)) | J31: =IF(C31=0,H31,D31) | K31: =IF(C31>=3,G31,J31*(1+Assumptions!$C$64)) | L31: =IF(C31=0,"ASSUMPTION",IF(C31<3,"Actual mean, banded","Actual P25 / mean / P90"))
A34: Notes carried in the file
A35: NO USAGE IS IN THIS FILE YET. Every metric is null. Nothing here is estimated. See pull-log.md.
A36: Shape: the sendblue block from the brief is removed. SendBlue is not in use: there is no SendBlue code, setting or dependency in any HaulOS repository or in the client site.
A37: 2026-10 is month-to-date (2026-10-01 to 2026-10-04).
A38: The Moving Group production: a second, read-only pass on 2026-10-04 did return monthly aggregates from the client site's Twilio account, Zoho CRM, the Zoho Voice call and text logs and the site database. They are NOT in this file: the session was not permitted to write them into the repository. They are held outside it until that is approved.
A39: Twilio (HaulOS account): UNAVAILABLE. No tool in the session is signed in to it. The two saved Twilio CLI profiles were identified by their TwiML application list only; neither has an application pointing at the HaulOS dialer backend, so neither was queried further. The desktop Twilio connector is bound to another project's account and has no usage endpoints. billed_costs_by_category is empty for the same reason.
A40: Zoho CRM (Kore org and sandbox): UNAVAILABLE. The HaulOS Zoho configuration tool holds settings-scope tokens (fields, layouts, pipeline, roles, profiles, views, workflows) and has no read path for org, users or records.
A41: Zoho Marketing Automation: UNAVAILABLE. Not in use; no tool.
A42: 10DLC brand and campaign status and fees for the HaulOS account: not retrievable (Twilio unavailable).
A43: PRIOR OBSERVATION, not from this pull (2026-09-30 probe of The Moving Group's Zoho Voice): 2 Zoho Voice users, 3 lines (2 that text, 1 calls only). Request-board card 63 (2026-09-03) records the plan as the Solo tier.
A44: PRIOR OBSERVATION, not from this pull (2026-10-01 capacity study of the client website): Zoho CRM API allowance 53,000 credits a day for The Moving Group's org; Zoho Voice documents 20 requests a minute; the client's own Twilio account held 7 numbers.
A45: PRIOR OBSERVATION, not from this pull (2026-10-01 capacity study): the Netlify team that hosts the client website is on the credit-based Pro plan ($20 for 3,000 credits) and was using about 9,000 credits a month (about $60), about 80% of it database compute kept awake by every-minute schedules; five sites share the credit pool.
...

Sheet UnitEconomics
A1: Unit economics
A2: Cost of each tool in use at low, base and high usage. Low and high are P25 and P90 of the actuals, or plus or minus the band on base when there are under three months.
A4: Line | B4: Unit | C4: Low | D4: Base | E4: High | F4: Note
A5: Usage, per dialer seat per month
A6: Billed minutes, PSTN outbound | B6: minutes | C6: =UsageActuals!$I$23 | D6: =UsageActuals!$J$23 | E6: =UsageActuals!$K$23
A7: Billed minutes, PSTN inbound | B7: minutes | C7: =UsageActuals!$I$24 | D7: =UsageActuals!$J$24 | E7: =UsageActuals!$K$24
A8: Billed minutes, browser leg | B8: minutes | C8: =UsageActuals!$I$25 | D8: =UsageActuals!$J$25 | E8: =UsageActuals!$K$25
A9: Recorded minutes | B9: minutes | C9: =UsageActuals!$I$26 | D9: =UsageActuals!$J$26 | E9: =UsageActuals!$K$26
A10: Calls | B10: calls | C10: =UsageActuals!$I$27 | D10: =UsageActuals!$J$27 | E10: =UsageActuals!$K$27
A11: Answering-machine-detection calls | B11: calls | C11: =UsageActuals!$I$28 | D11: =UsageActuals!$J$28 | E11: =UsageActuals!$K$28
A12: Phone minutes a customer would count | B12: minutes | C12: =C6+C7 | D12: =D6+D7 | E12: =E6+E7 | F12: Outbound plus inbound. This is what an included-minutes allowance is measured in.
A14: Usage, per tenant per month
A15: Outbound SMS segments | B15: segments | C15: =UsageActuals!$I$29*Assumptions!$C$41 | D15: =UsageActuals!$J$29*Assumptions!$C$41 | E15: =UsageActuals!$K$29*Assumptions!$C$41 | F15: Per seat, times the seats.
A16: Inbound SMS segments | B16: segments | C16: =UsageActuals!$I$30*Assumptions!$C$41 | D16: =UsageActuals!$J$30*Assumptions!$C$41 | E16: =UsageActuals!$K$30*Assumptions!$C$41
A17: AI conversations | B17: conversations | C17: =UsageActuals!$I$31 | D17: =UsageActuals!$J$31 | E17: =UsageActuals!$K$31
A19: Twilio Programmable Voice: cost per dialer seat per month
A20: PSTN outbound | B20: $ | C20: =C6*Assumptions!$C$93 | D20: =D6*Assumptions!$C$93 | E20: =E6*Assumptions!$C$93
A21: PSTN inbound | B21: $ | C21: =C7*Assumptions!$C$94 | D21: =D7*Assumptions!$C$94 | E21: =E7*Assumptions!$C$94
A22: Browser leg | B22: $ | C22: =C8*Assumptions!$C$95 | D22: =D8*Assumptions!$C$95 | E22: =E8*Assumptions!$C$95
A23: Recording | B23: $ | C23: =C9*Assumptions!$C$96 | D23: =D9*Assumptions!$C$96 | E23: =E9*Assumptions!$C$96
A24: Recording storage, steady state | B24: $ | C24: =C9*Assumptions!$C$97*Assumptions!$C$62 | D24: =D9*Assumptions!$C$97*Assumptions!$C$62 | E24: =E9*Assumptions!$C$97*Assumptions!$C$62 | F24: Each month of recordings is stored for the retention period. With no retention rule this keeps growing.
A25: Answering machine detection | B25: $ | C25: =C11*Assumptions!$C$99 | D25: =D11*Assumptions!$C$99 | E25: =E11*Assumptions!$C$99
A26: Voice usage per seat | B26: $ | C26: =C20+C21+C22+C23+C24+C25 | D26: =D20+D21+D22+D23+D24+D25 | E26: =E20+E21+E22+E23+E24+E25
A27: Cost per phone minute | B27: $ / minute | C27: =IF(C12>0,C26/C12,0) | D27: =IF(D12>0,D26/D12,0) | E27: =IF(E12>0,E26/E12,0)
A28: Phone numbers per tenant | B28: $ | C28: =(Assumptions!$C$41*Assumptions!$C$42+Assumptions!$C$43)*Assumptions!$C$98 | D28: =(Assumptions!$C$41*Assumptions!$C$42+Assumptions!$C$43)*Assumptions!$C$98 | E28: =(Assumptions!$C$41*Assumptions!$C$42+Assumptions!$C$43)*Assumptions!$C$98
A29: Voice per tenant | B29: $ | C29: =Assumptions!$C$41*C26+C28 | D29: =Assumptions!$C$41*D26+D28 | E29: =Assumptions!$C$41*E26+E28
A30: Voice per seat, numbers included | B30: $ | C30: =C29/Assumptions!$C$41 | D30: =D29/Assumptions!$C$41 | E30: =E29/Assumptions!$C$41
A31: Overage price per phone minute | B31: $ / minute | C31: =ROUNDUP(Assumptions!$C$24*$D$27,3) | D31: =ROUNDUP(Assumptions!$C$24*$D$27,3) | E31: =ROUNDUP(Assumptions!$C$24*$D$27,3) | F31: One price for every tenant, set from the base cost.
A33: Twilio Messaging and 10DLC: cost per tenant per month
A34: Outbound segments, carrier fee included | B34: $ | C34: =C15*(Assumptions!$C$102+Assumptions!$C$104) | D34: =D15*(Assumptions!$C$102+Assumptions!$C$104) | E34: =E15*(Assumptions!$C$102+Assumptions!$C$104)
A35: Inbound segments, carrier fee included | B35: $ | C35: =C16*(Assumptions!$C$103+Assumptions!$C$105) | D35: =D16*(Assumptions!$C$103+Assumptions!$C$105) | E35: =E16*(Assumptions!$C$103+Assumptions!$C$105)
A36: Campaign fee and texting number | B36: $ | C36: =Assumptions!$C$108+Assumptions!$C$109*Assumptions!$C$98 | D36: =Assumptions!$C$108+Assumptions!$C$109*Assumptions!$C$98 | E36: =Assumptions!$C$108+Assumptions!$C$109*Assumptions!$C$98
A37: Texting per tenant | B37: $ | C37: =C34+C35+C36 | D37: =D34+D35+D36 | E37: =E34+E35+E36
A38: Cost per outbound segment | B38: $ / segment | C38: =Assumptions!$C$102+Assumptions!$C$104 | D38: =Assumptions!$C$102+Assumptions!$C$104 | E38: =Assumptions!$C$102+Assumptions!$C$104
A39: Overage price per segment | B39: $ / segment | C39: =ROUNDUP(Assumptions!$C$24*C38,3) | D39: =ROUNDUP(Assumptions!$C$24*D38,3) | E39: =ROUNDUP(Assumptions!$C$24*E38,3)
A40: One-time: brand and campaign registration | B40: $ | C40: =Assumptions!$C$106+Assumptions!$C$107 | D40: =Assumptions!$C$106+Assumptions!$C$107 | E40: =Assumptions!$C$106+Assumptions!$C$107
A42: Zoho CRM: the tenant pays Zoho
A43: List price per seat | B43: $ | C43: =Assumptions!$C$116 | D43: =Assumptions!$C$116 | E43: =Assumptions!$C$116
A44: List price per tenant | B44: $ | C44: =Assumptions!$C$116*Assumptions!$C$41 | D44: =Assumptions!$C$116*Assumptions!$C$41 | E44: =Assumptions!$C$116*Assumptions!$C$41
A45: Kore margin per tenant | B45: $ | C45: =Assumptions!$C$37*Assumptions!$C$116*Assumptions!$C$41 | D45: =Assumptions!$C$37*Assumptions!$C$116*Assumptions!$C$41 | E45: =Assumptions!$C$37*Assumptions!$C$116*Assumptions!$C$41
...

Sheet VoiceSKUs
A1: Voice: Zoho Voice (A) against the custom Twilio dialer (B)
A2: A costs Kore nothing and earns the reseller margin. B is priced by Kore and carries the Twilio bill.
A4: Line | B4: Unit | C4: Low | D4: Base | E4: High | F4: Note
A5: A. Zoho Voice, per seat per month
A6: What the tenant pays Zoho | B6: $ | C6: =Assumptions!$C$123 | D6: =Assumptions!$C$123 | E6: =Assumptions!$C$123 | F6: Enterprise Telephony Basic, with unlimited US and Canada calling.
A7: What Kore earns | B7: $ | C7: =Assumptions!$C$37*Assumptions!$C$123 | D7: =Assumptions!$C$37*Assumptions!$C$123 | E7: =Assumptions!$C$37*Assumptions!$C$123 | F7: Reseller margin. 0% today.
A8: What Kore pays | B8: $ | C8: =0 | D8: =0 | E8: =0
A9: Kore gross profit per seat | B9: $ | C9: =C7-C8 | D9: =D7-D8 | E9: =E7-E8
A10: Tenant price with the auto dialer (planned) | B10: $ | C10: =Assumptions!$C$123+Assumptions!$C$125 | D10: =Assumptions!$C$123+Assumptions!$C$125 | E10: =Assumptions!$C$123+Assumptions!$C$125 | F10: ASSUMPTION: no auto dialer price is published.
A12: B. Custom Twilio dialer, per seat per month
A13: Price | B13: $ | C13: =Assumptions!$C$22 | D13: =Assumptions!$C$22 | E13: =Assumptions!$C$22
A14: Minutes included | B14: minutes | C14: =Assumptions!$C$23 | D14: =Assumptions!$C$23 | E14: =Assumptions!$C$23
A15: Phone minutes used | B15: minutes | C15: =UnitEconomics!$C$12 | D15: =UnitEconomics!$D$12 | E15: =UnitEconomics!$E$12
A16: Cost, numbers included | B16: $ | C16: =UnitEconomics!$C$30 | D16: =UnitEconomics!$D$30 | E16: =UnitEconomics!$E$30
A17: Gross profit, no overage charged | B17: $ | C17: =C13-C16 | D17: =D13-D16 | E17: =E13-E16
A18: Gross margin, no overage charged | B18: % | C18: =C17/C13 | D18: =D17/D13 | E18: =E17/E13
A19: Minutes over the allowance | B19: minutes | C19: =MAX(0,C15-C14) | D19: =MAX(0,D15-D14) | E19: =MAX(0,E15-E14)
A20: Overage price | B20: $ / minute | C20: =UnitEconomics!$C$31 | D20: =UnitEconomics!$D$31 | E20: =UnitEconomics!$E$31
A21: Overage revenue | B21: $ | C21: =Assumptions!$C$25*C19*C20 | D21: =Assumptions!$C$25*D19*D20 | E21: =Assumptions!$C$25*E19*E20
A22: Revenue with overage | B22: $ | C22: =C13+C21 | D22: =D13+D21 | E22: =E13+E21
A23: Gross profit with overage | B23: $ | C23: =C22-C16 | D23: =D22-D16 | E23: =E22-E16
A24: Gross margin with overage | B24: % | C24: =C23/C22 | D24: =D23/D22 | E24: =E23/E22
A26: B against A
A27: What the tenant pays extra for B, per seat | B27: $ | C27: =C13-C6 | D27: =D13-D6 | E27: =E13-E6 | F27: Before overage. A has no minute cap.
A28: The same, against A with the auto dialer | B28: $ | C28: =C13-C10 | D28: =D13-D10 | E28: =E13-E10
A29: What Kore earns extra from B, per seat | B29: $ | C29: =C23-C9 | D29: =D23-D9 | E29: =E23-E9
A31: Breakeven
A32: Minutes a seat can use before the flat price loses money | B32: minutes | C32: =(Assumptions!$C$22-((Assumptions!$C$41*Assumptions!$C$42+Assumptions!$C$43)*Assumptions!$C$98/Assumptions!$C$41))/UnitEconomics!$C$27 | D32: =(Assumptions!$C$22-((Assumptions!$C$41*Assumptions!$C$42+Assumptions!$C$43)*Assumptions!$C$98/Assumptions!$C$41))/UnitEconomics!$D$27 | E32: =(Assumptions!$C$22-((Assumptions!$C$41*Assumptions!$C$42+Assumptions!$C$43)*Assumptions!$C$98/Assumptions!$C$41))/UnitEconomics!$E$27 | F32: With no overage charged.
A33: Minutes a seat can use and still hit the margin target | B33: minutes | C33: =(Assumptions!$C$22*(1-Assumptions!$C$38)-((Assumptions!$C$41*Assumptions!$C$42+Assumptions!$C$43)*Assumptions!$C$98/Assumptions!$C$41))/UnitEconomics!$C$27 | D33: =(Assumptions!$C$22*(1-Assumptions!$C$38)-((Assumptions!$C$41*Assumptions!$C$42+Assumptions!$C$43)*Assumptions!$C$98/Assumptions!$C$41))/UnitEconomics!$D$27 | E33: =(Assumptions!$C$22*(1-Assumptions!$C$38)-((Assumptions!$C$41*Assumptions!$C$42+Assumptions!$C$43)*Assumptions!$C$98/Assumptions!$C$41))/UnitEconomics!$E$27
A34: Minutes at which B earns Kore no more than reselling A | B34: minutes | C34: =(Assumptions!$C$22-Assumptions!$C$37*Assumptions!$C$123-((Assumptions!$C$41*Assumptions!$C$42+Assumptions!$C$43)*Assumptions!$C$98/Assumptions!$C$41))/UnitEconomics!$C$27 | D34: =(Assumptions!$C$22-Assumptions!$C$37*Assumptions!$C$123-((Assumptions!$C$41*Assumptions!$C$42+Assumptions!$C$43)*Assumptions!$C$98/Assumptions!$C$41))/UnitEconomics!$D$27 | E34: =(Assumptions!$C$22-Assumptions!$C$37*Assumptions!$C$123-((Assumptions!$C$41*Assumptions!$C$42+Assumptions!$C$43)*Assumptions!$C$98/Assumptions!$C$41))/UnitEconomics!$E$27
A35: Fixed monthly cost of running the dialer | B35: $ | C35: =UnitEconomics!$C$64*Assumptions!$C$17 | D35: =UnitEconomics!$D$64*Assumptions!$C$17 | E35: =UnitEconomics!$E$64*Assumptions!$C$17 | F35: Backend hosting today.
A36: Seats needed to cover that fixed cost | B36: seats | C36: =IF(C29>0,C35/C29,"never") | D36: =IF(D29>0,D35/D29,"never") | E36: =IF(E29>0,E35/E29,"never")
A38: Margin by minutes used (base cost per minute)
A39: Phone minutes per seat | B39: Cost per seat | C39: Margin, flat price | D39: Overage revenue | E39: Margin with overage
A40: 500 | B40: =A40*UnitEconomics!$D$27+((Assumptions!$C$41*Assumptions!$C$42+Assumptions!$C$43)*Assumptions!$C$98/Assumptions!$C$41) | C40: =(Assumptions!$C$22-B40)/Assumptions!$C$22 | D40: =Assumptions!$C$25*MAX(0,A40-Assumptions!$C$23)*UnitEconomics!$D$31 | E40: =(Assumptions!$C$22+D40-B40)/(Assumptions!$C$22+D40)
A41: 800 | B41: =A41*UnitEconomics!$D$27+((Assumptions!$C$41*Assumptions!$C$42+Assumptions!$C$43)*Assumptions!$C$98/Assumptions!$C$41) | C41: =(Assumptions!$C$22-B41)/Assumptions!$C$22 | D41: =Assumptions!$C$25*MAX(0,A41-Assumptions!$C$23)*UnitEconomics!$D$31 | E41: =(Assumptions!$C$22+D41-B41)/(Assumptions!$C$22+D41)
A42: 1000 | B42: =A42*UnitEconomics!$D$27+((Assumptions!$C$41*Assumptions!$C$42+Assumptions!$C$43)*Assumptions!$C$98/Assumptions!$C$41) | C42: =(Assumptions!$C$22-B42)/Assumptions!$C$22 | D42: =Assumptions!$C$25*MAX(0,A42-Assumptions!$C$23)*UnitEconomics!$D$31 | E42: =(Assumptions!$C$22+D42-B42)/(Assumptions!$C$22+D42)
A43: 1200 | B43: =A43*UnitEconomics!$D$27+((Assumptions!$C$41*Assumptions!$C$42+Assumptions!$C$43)*Assumptions!$C$98/Assumptions!$C$41) | C43: =(Assumptions!$C$22-B43)/Assumptions!$C$22 | D43: =Assumptions!$C$25*MAX(0,A43-Assumptions!$C$23)*UnitEconomics!$D$31 | E43: =(Assumptions!$C$22+D43-B43)/(Assumptions!$C$22+D43)
A44: 1500 | B44: =A44*UnitEconomics!$D$27+((Assumptions!$C$41*Assumptions!$C$42+Assumptions!$C$43)*Assumptions!$C$98/Assumptions!$C$41) | C44: =(Assumptions!$C$22-B44)/Assumptions!$C$22 | D44: =Assumptions!$C$25*MAX(0,A44-Assumptions!$C$23)*UnitEconomics!$D$31 | E44: =(Assumptions!$C$22+D44-B44)/(Assumptions!$C$22+D44)
A45: 2000 | B45: =A45*UnitEconomics!$D$27+((Assumptions!$C$41*Assumptions!$C$42+Assumptions!$C$43)*Assumptions!$C$98/Assumptions!$C$41) | C45: =(Assumptions!$C$22-B45)/Assumptions!$C$22 | D45: =Assumptions!$C$25*MAX(0,A45-Assumptions!$C$23)*UnitEconomics!$D$31 | E45: =(Assumptions!$C$22+D45-B45)/(Assumptions!$C$22+D45)
...

Sheet Tiers
A1: Tiers: platform fee and add-ons
A2: Revenue and cost per tenant, blended by attach rate. Costs are the base case from UnitEconomics. Gross margin here is tool cost only: no support, sales or payment fees.
A4: Item | B4: Price | C4: Unit | D4: Units per tenant | E4: Attach rate | F4: Revenue per tenant that takes it | G4: Blended revenue per tenant | H4: Cost per tenant that takes it | I4: Blended cost per tenant | J4: Gross profit per tenant that takes it | K4: Gross margin
A5: Platform | B5: =Assumptions!$C$21 | C5: $ / tenant | D5: =1 | E5: =1 | F5: =B5*D5 | G5: =F5*E5 | H5: =UnitEconomics!$D$71 | I5: =H5*E5 | J5: =F5-H5 | K5: =IF(F5>0,J5/F5,0)
A6: Dialer | B6: =Assumptions!$C$22 | C6: $ / seat | D6: =Assumptions!$C$41 | E6: =Assumptions!$C$33 | F6: =B6*D6 | G6: =F6*E6 | H6: =UnitEconomics!$D$72 | I6: =H6*E6 | J6: =F6-H6 | K6: =IF(F6>0,J6/F6,0)
A7: Dialer overage | B7: =UnitEconomics!$D$31 | C7: $ / minute | D7: =Assumptions!$C$41*MAX(0,UnitEconomics!$D$12-Assumptions!$C$23) | E7: =Assumptions!$C$33*Assumptions!$C$25 | F7: =B7*D7 | G7: =F7*E7 | H7: =0 | I7: =H7*E7 | J7: =F7-H7 | K7: =IF(F7>0,J7/F7,0)
A8: SMS | B8: =Assumptions!$C$26 | C8: $ / tenant | D8: =1 | E8: =Assumptions!$C$34 | F8: =B8*D8 | G8: =F8*E8 | H8: =UnitEconomics!$D$73 | I8: =H8*E8 | J8: =F8-H8 | K8: =IF(F8>0,J8/F8,0)
A9: SMS overage | B9: =UnitEconomics!$D$39 | C9: $ / segment | D9: =MAX(0,UnitEconomics!$D$15-Assumptions!$C$27) | E9: =Assumptions!$C$34*Assumptions!$C$25 | F9: =B9*D9 | G9: =F9*E9 | H9: =0 | I9: =H9*E9 | J9: =F9-H9 | K9: =IF(F9>0,J9/F9,0)
A10: Compliance | B10: =Assumptions!$C$29 | C10: $ / tenant | D10: =1 | E10: =Assumptions!$C$35 | F10: =B10*D10 | G10: =F10*E10 | H10: =UnitEconomics!$D$74 | I10: =H10*E10 | J10: =F10-H10 | K10: =IF(F10>0,J10/F10,0)
A11: AI SMS | B11: =Assumptions!$C$30 | C11: $ / tenant | D11: =1 | E11: =Assumptions!$C$36 | F11: =B11*D11 | G11: =F11*E11 | H11: =UnitEconomics!$D$75 | I11: =H11*E11 | J11: =F11-H11 | K11: =IF(F11>0,J11/F11,0)
A12: Zoho resale margin | B12: =Assumptions!$C$37*(Assumptions!$C$116*Assumptions!$C$41+Assumptions!$C$123*Assumptions!$C$41*(1-Assumptions!$C$33)) | C12: $ / tenant | D12: =1 | E12: =1 | F12: =B12*D12 | G12: =F12*E12 | H12: =0 | I12: =H12*E12 | J12: =F12-H12 | K12: =IF(F12>0,J12/F12,0)
A14: Per tenant per month, blended
A15: Revenue per tenant (ARPA) | B15: =SUM(G5:G12)
A16: Revenue per tenant per year | B16: =$B$15*12
A17: Revenue per tenant with no overage | B17: =$B$15-G7-G9
A18: Cost per tenant | B18: =SUM(I5:I12)
A19: Gross profit per tenant | B19: =$B$15-$B$18
A20: Gross margin | B20: =IF($B$15>0,$B$19/$B$15,0)
A21: Gross margin with no overage | B21: =IF($B$17>0,($B$17-$B$18)/$B$17,0)
A23: Used by the forecast
A24: Add-on revenue per tenant, blended | B24: =G6+G8+G10+G11
A25: Overage and resale revenue per tenant, blended | B25: =G7+G9+G12
A26: Cost per tenant, blended, without hosting and client site | B26: =$B$18-I5
A27: One-time fees per new tenant | B27: =Assumptions!$C$31+Assumptions!$C$34*Assumptions!$C$28
A28: One-time cost per new tenant | B28: =Assumptions!$C$34*UnitEconomics!$D$40
A30: Margin by add-on, overage folded in (per tenant that takes it)
A31: Add-on | B31: Revenue | C31: Cost | D31: Gross profit | E31: Gross margin | F31: Gross margin with no overage
A32: Platform | B32: =F5 | C32: =H5 | D32: =B32-C32 | E32: =IF(B32>0,D32/B32,0) | F32: =IF(F5>0,(F5-C32)/(F5),0)
A33: Dialer | B33: =F6+Assumptions!$C$25*F7 | C33: =H6 | D33: =B33-C33 | E33: =IF(B33>0,D33/B33,0) | F33: =IF(F6>0,(F6-C33)/(F6),0)
A34: SMS | B34: =F8+Assumptions!$C$25*F9 | C34: =H8 | D34: =B34-C34 | E34: =IF(B34>0,D34/B34,0) | F34: =IF(F8>0,(F8-C34)/(F8),0)
A35: Compliance | B35: =F10 | C35: =H10 | D35: =B35-C35 | E35: =IF(B35>0,D35/B35,0) | F35: =IF(F10>0,(F10-C35)/(F10),0)
A36: AI SMS | B36: =F11 | C36: =H11 | D36: =B36-C36 | E36: =IF(B36>0,D36/B36,0) | F36: =IF(F11>0,(F11-C36)/(F11),0)
A38: Bundles (1 = in the bundle)
A39: Item | B39: Core | C39: Growth | D39: Complete
A40: Platform | B40: 1 | C40: 1 | D40: 1
A41: Dialer, all seats | B41: 0 | C41: 1 | D41: 1
A42: SMS | B42: 0 | C42: 1 | D42: 1
A43: Compliance | B43: 0 | C43: 0 | D43: 1
A44: AI SMS | B44: 0 | C44: 0 | D44: 1
A45: Price per month | B45: =(B40*$F$5+B41*$F$6+B42*$F$8+B43*$F$10+B44*$F$11)*(1-Assumptions!$C$32) | C45: =(C40*$F$5+C41*$F$6+C42*$F$8+C43*$F$10+C44*$F$11)*(1-Assumptions!$C$32) | D45: =(D40*$F$5+D41*$F$6+D42*$F$8+D43*$F$10+D44*$F$11)*(1-Assumptions!$C$32)
...

Sheet Hosting
A1: Hosting: Forge and AWS today, Azure at scale
A2: The switch is host_mode on the Assumptions sheet: 1 Forge and AWS, 2 Azure, 3 Azure from a tenant count.
A5: One server, all-in | B5: $ / month | C5: =Assumptions!$C$136+Assumptions!$C$137*Assumptions!$C$138+Assumptions!$C$139 | D5: Instance, disk and public address.
A6: Azure cost that grows with each tenant | B6: $ / tenant / month | C6: =Assumptions!$C$148/10000*Assumptions!$C$147+Assumptions!$C$150*Assumptions!$C$149+Assumptions!$C$152*Assumptions!$C$151+Assumptions!$C$154/10000*Assumptions!$C$153 | D6: Key Vault operations, Blob and Table storage, Table transactions.
A7: Switch (host_mode) | C7: =Assumptions!$C$155 | D7: =CHOOSE(C7,"Forge and AWS","Azure","Azure from "&Assumptions!$C$156&" tenants")
A9: Tenants | B9: Servers | C9: Forge and AWS, $ / month | D9: Per tenant | E9: Instances | F9: Azure, $ / month | G9: Per tenant | H9: Selected, $ / month | I9: Selected per tenant | J9: Client sites, $ / month | K9: Per tenant | L9: Hosting and site per tenant
A10: 1 | B10: =ROUNDUP($A10/Assumptions!$C$141,0) | C10: =(Assumptions!$C$135*Assumptions!$C$140+Hosting!$C$5*Assumptions!$C$140+MAX(0,ROUNDUP($A10/Assumptions!$C$141,0)-1)*Hosting!$C$5) | D10: =C10/$A10 | E10: =MAX(Assumptions!$C$145,ROUNDUP($A10/Assumptions!$C$146,0)) | F10: =(MAX(Assumptions!$C$145,ROUNDUP($A10/Assumptions!$C$146,0))*Assumptions!$C$144+$A10*Hosting!$C$6) | G10: =F10/$A10 | H10: =IF(Assumptions!$C$155=1,(Assumptions!$C$135*Assumptions!$C$140+Hosting!$C$5*Assumptions!$C$140+MAX(0,ROUNDUP($A10/Assumptions!$C$141,0)-1)*Hosting!$C$5),IF(Assumptions!$C$155=2,(MAX(Assumptions!$C$145,ROUNDUP($A10/Assumptions!$C$146,0))*Assumptions!$C$144+$A10*Hosting!$C$6),IF($A10>=Assumptions!$C$156,(MAX(Assumptions!$C$145,ROUNDUP($A10/Assumptions!$C$146,0))*Assumptions!$C$144+$A10*Hosting!$C$6),(Assumptions!$C$135*Assumptions!$C$140+Hosting!$C$5*Assumptions!$C$140+MAX(0,ROUNDUP($A10/Assumptions!$C$141,0)-1)*Hosting!$C$5)))) | I10: =H10/$A10 | J10: =Assumptions!$C$159*(Assumptions!$C$160+MAX(0,$A10*Assumptions!$C$163-Assumptions!$C$161)*Assumptions!$C$162) | K10: =J10/$A10 | L10: =I10+K10
A11: 2 | B11: =ROUNDUP($A11/Assumptions!$C$141,0) | C11: =(Assumptions!$C$135*Assumptions!$C$140+Hosting!$C$5*Assumptions!$C$140+MAX(0,ROUNDUP($A11/Assumptions!$C$141,0)-1)*Hosting!$C$5) | D11: =C11/$A11 | E11: =MAX(Assumptions!$C$145,ROUNDUP($A11/Assumptions!$C$146,0)) | F11: =(MAX(Assumptions!$C$145,ROUNDUP($A11/Assumptions!$C$146,0))*Assumptions!$C$144+$A11*Hosting!$C$6) | G11: =F11/$A11 | H11: =IF(Assumptions!$C$155=1,(Assumptions!$C$135*Assumptions!$C$140+Hosting!$C$5*Assumptions!$C$140+MAX(0,ROUNDUP($A11/Assumptions!$C$141,0)-1)*Hosting!$C$5),IF(Assumptions!$C$155=2,(MAX(Assumptions!$C$145,ROUNDUP($A11/Assumptions!$C$146,0))*Assumptions!$C$144+$A11*Hosting!$C$6),IF($A11>=Assumptions!$C$156,(MAX(Assumptions!$C$145,ROUNDUP($A11/Assumptions!$C$146,0))*Assumptions!$C$144+$A11*Hosting!$C$6),(Assumptions!$C$135*Assumptions!$C$140+Hosting!$C$5*Assumptions!$C$140+MAX(0,ROUNDUP($A11/Assumptions!$C$141,0)-1)*Hosting!$C$5)))) | I11: =H11/$A11 | J11: =Assumptions!$C$159*(Assumptions!$C$160+MAX(0,$A11*Assumptions!$C$163-Assumptions!$C$161)*Assumptions!$C$162) | K11: =J11/$A11 | L11: =I11+K11
A12: 5 | B12: =ROUNDUP($A12/Assumptions!$C$141,0) | C12: =(Assumptions!$C$135*Assumptions!$C$140+Hosting!$C$5*Assumptions!$C$140+MAX(0,ROUNDUP($A12/Assumptions!$C$141,0)-1)*Hosting!$C$5) | D12: =C12/$A12 | E12: =MAX(Assumptions!$C$145,ROUNDUP($A12/Assumptions!$C$146,0)) | F12: =(MAX(Assumptions!$C$145,ROUNDUP($A12/Assumptions!$C$146,0))*Assumptions!$C$144+$A12*Hosting!$C$6) | G12: =F12/$A12 | H12: =IF(Assumptions!$C$155=1,(Assumptions!$C$135*Assumptions!$C$140+Hosting!$C$5*Assumptions!$C$140+MAX(0,ROUNDUP($A12/Assumptions!$C$141,0)-1)*Hosting!$C$5),IF(Assumptions!$C$155=2,(MAX(Assumptions!$C$145,ROUNDUP($A12/Assumptions!$C$146,0))*Assumptions!$C$144+$A12*Hosting!$C$6),IF($A12>=Assumptions!$C$156,(MAX(Assumptions!$C$145,ROUNDUP($A12/Assumptions!$C$146,0))*Assumptions!$C$144+$A12*Hosting!$C$6),(Assumptions!$C$135*Assumptions!$C$140+Hosting!$C$5*Assumptions!$C$140+MAX(0,ROUNDUP($A12/Assumptions!$C$141,0)-1)*Hosting!$C$5)))) | I12: =H12/$A12 | J12: =Assumptions!$C$159*(Assumptions!$C$160+MAX(0,$A12*Assumptions!$C$163-Assumptions!$C$161)*Assumptions!$C$162) | K12: =J12/$A12 | L12: =I12+K12
A13: 10 | B13: =ROUNDUP($A13/Assumptions!$C$141,0) | C13: =(Assumptions!$C$135*Assumptions!$C$140+Hosting!$C$5*Assumptions!$C$140+MAX(0,ROUNDUP($A13/Assumptions!$C$141,0)-1)*Hosting!$C$5) | D13: =C13/$A13 | E13: =MAX(Assumptions!$C$145,ROUNDUP($A13/Assumptions!$C$146,0)) | F13: =(MAX(Assumptions!$C$145,ROUNDUP($A13/Assumptions!$C$146,0))*Assumptions!$C$144+$A13*Hosting!$C$6) | G13: =F13/$A13 | H13: =IF(Assumptions!$C$155=1,(Assumptions!$C$135*Assumptions!$C$140+Hosting!$C$5*Assumptions!$C$140+MAX(0,ROUNDUP($A13/Assumptions!$C$141,0)-1)*Hosting!$C$5),IF(Assumptions!$C$155=2,(MAX(Assumptions!$C$145,ROUNDUP($A13/Assumptions!$C$146,0))*Assumptions!$C$144+$A13*Hosting!$C$6),IF($A13>=Assumptions!$C$156,(MAX(Assumptions!$C$145,ROUNDUP($A13/Assumptions!$C$146,0))*Assumptions!$C$144+$A13*Hosting!$C$6),(Assumptions!$C$135*Assumptions!$C$140+Hosting!$C$5*Assumptions!$C$140+MAX(0,ROUNDUP($A13/Assumptions!$C$141,0)-1)*Hosting!$C$5)))) | I13: =H13/$A13 | J13: =Assumptions!$C$159*(Assumptions!$C$160+MAX(0,$A13*Assumptions!$C$163-Assumptions!$C$161)*Assumptions!$C$162) | K13: =J13/$A13 | L13: =I13+K13
A14: 25 | B14: =ROUNDUP($A14/Assumptions!$C$141,0) | C14: =(Assumptions!$C$135*Assumptions!$C$140+Hosting!$C$5*Assumptions!$C$140+MAX(0,ROUNDUP($A14/Assumptions!$C$141,0)-1)*Hosting!$C$5) | D14: =C14/$A14 | E14: =MAX(Assumptions!$C$145,ROUNDUP($A14/Assumptions!$C$146,0)) | F14: =(MAX(Assumptions!$C$145,ROUNDUP($A14/Assumptions!$C$146,0))*Assumptions!$C$144+$A14*Hosting!$C$6) | G14: =F14/$A14 | H14: =IF(Assumptions!$C$155=1,(Assumptions!$C$135*Assumptions!$C$140+Hosting!$C$5*Assumptions!$C$140+MAX(0,ROUNDUP($A14/Assumptions!$C$141,0)-1)*Hosting!$C$5),IF(Assumptions!$C$155=2,(MAX(Assumptions!$C$145,ROUNDUP($A14/Assumptions!$C$146,0))*Assumptions!$C$144+$A14*Hosting!$C$6),IF($A14>=Assumptions!$C$156,(MAX(Assumptions!$C$145,ROUNDUP($A14/Assumptions!$C$146,0))*Assumptions!$C$144+$A14*Hosting!$C$6),(Assumptions!$C$135*Assumptions!$C$140+Hosting!$C$5*Assumptions!$C$140+MAX(0,ROUNDUP($A14/Assumptions!$C$141,0)-1)*Hosting!$C$5)))) | I14: =H14/$A14 | J14: =Assumptions!$C$159*(Assumptions!$C$160+MAX(0,$A14*Assumptions!$C$163-Assumptions!$C$161)*Assumptions!$C$162) | K14: =J14/$A14 | L14: =I14+K14
A15: 50 | B15: =ROUNDUP($A15/Assumptions!$C$141,0) | C15: =(Assumptions!$C$135*Assumptions!$C$140+Hosting!$C$5*Assumptions!$C$140+MAX(0,ROUNDUP($A15/Assumptions!$C$141,0)-1)*Hosting!$C$5) | D15: =C15/$A15 | E15: =MAX(Assumptions!$C$145,ROUNDUP($A15/Assumptions!$C$146,0)) | F15: =(MAX(Assumptions!$C$145,ROUNDUP($A15/Assumptions!$C$146,0))*Assumptions!$C$144+$A15*Hosting!$C$6) | G15: =F15/$A15 | H15: =IF(Assumptions!$C$155=1,(Assumptions!$C$135*Assumptions!$C$140+Hosting!$C$5*Assumptions!$C$140+MAX(0,ROUNDUP($A15/Assumptions!$C$141,0)-1)*Hosting!$C$5),IF(Assumptions!$C$155=2,(MAX(Assumptions!$C$145,ROUNDUP($A15/Assumptions!$C$146,0))*Assumptions!$C$144+$A15*Hosting!$C$6),IF($A15>=Assumptions!$C$156,(MAX(Assumptions!$C$145,ROUNDUP($A15/Assumptions!$C$146,0))*Assumptions!$C$144+$A15*Hosting!$C$6),(Assumptions!$C$135*Assumptions!$C$140+Hosting!$C$5*Assumptions!$C$140+MAX(0,ROUNDUP($A15/Assumptions!$C$141,0)-1)*Hosting!$C$5)))) | I15: =H15/$A15 | J15: =Assumptions!$C$159*(Assumptions!$C$160+MAX(0,$A15*Assumptions!$C$163-Assumptions!$C$161)*Assumptions!$C$162) | K15: =J15/$A15 | L15: =I15+K15
A16: 100 | B16: =ROUNDUP($A16/Assumptions!$C$141,0) | C16: =(Assumptions!$C$135*Assumptions!$C$140+Hosting!$C$5*Assumptions!$C$140+MAX(0,ROUNDUP($A16/Assumptions!$C$141,0)-1)*Hosting!$C$5) | D16: =C16/$A16 | E16: =MAX(Assumptions!$C$145,ROUNDUP($A16/Assumptions!$C$146,0)) | F16: =(MAX(Assumptions!$C$145,ROUNDUP($A16/Assumptions!$C$146,0))*Assumptions!$C$144+$A16*Hosting!$C$6) | G16: =F16/$A16 | H16: =IF(Assumptions!$C$155=1,(Assumptions!$C$135*Assumptions!$C$140+Hosting!$C$5*Assumptions!$C$140+MAX(0,ROUNDUP($A16/Assumptions!$C$141,0)-1)*Hosting!$C$5),IF(Assumptions!$C$155=2,(MAX(Assumptions!$C$145,ROUNDUP($A16/Assumptions!$C$146,0))*Assumptions!$C$144+$A16*Hosting!$C$6),IF($A16>=Assumptions!$C$156,(MAX(Assumptions!$C$145,ROUNDUP($A16/Assumptions!$C$146,0))*Assumptions!$C$144+$A16*Hosting!$C$6),(Assumptions!$C$135*Assumptions!$C$140+Hosting!$C$5*Assumptions!$C$140+MAX(0,ROUNDUP($A16/Assumptions!$C$141,0)-1)*Hosting!$C$5)))) | I16: =H16/$A16 | J16: =Assumptions!$C$159*(Assumptions!$C$160+MAX(0,$A16*Assumptions!$C$163-Assumptions!$C$161)*Assumptions!$C$162) | K16: =J16/$A16 | L16: =I16+K16
A17: 250 | B17: =ROUNDUP($A17/Assumptions!$C$141,0) | C17: =(Assumptions!$C$135*Assumptions!$C$140+Hosting!$C$5*Assumptions!$C$140+MAX(0,ROUNDUP($A17/Assumptions!$C$141,0)-1)*Hosting!$C$5) | D17: =C17/$A17 | E17: =MAX(Assumptions!$C$145,ROUNDUP($A17/Assumptions!$C$146,0)) | F17: =(MAX(Assumptions!$C$145,ROUNDUP($A17/Assumptions!$C$146,0))*Assumptions!$C$144+$A17*Hosting!$C$6) | G17: =F17/$A17 | H17: =IF(Assumptions!$C$155=1,(Assumptions!$C$135*Assumptions!$C$140+Hosting!$C$5*Assumptions!$C$140+MAX(0,ROUNDUP($A17/Assumptions!$C$141,0)-1)*Hosting!$C$5),IF(Assumptions!$C$155=2,(MAX(Assumptions!$C$145,ROUNDUP($A17/Assumptions!$C$146,0))*Assumptions!$C$144+$A17*Hosting!$C$6),IF($A17>=Assumptions!$C$156,(MAX(Assumptions!$C$145,ROUNDUP($A17/Assumptions!$C$146,0))*Assumptions!$C$144+$A17*Hosting!$C$6),(Assumptions!$C$135*Assumptions!$C$140+Hosting!$C$5*Assumptions!$C$140+MAX(0,ROUNDUP($A17/Assumptions!$C$141,0)-1)*Hosting!$C$5)))) | I17: =H17/$A17 | J17: =Assumptions!$C$159*(Assumptions!$C$160+MAX(0,$A17*Assumptions!$C$163-Assumptions!$C$161)*Assumptions!$C$162) | K17: =J17/$A17 | L17: =I17+K17
A18: 500 | B18: =ROUNDUP($A18/Assumptions!$C$141,0) | C18: =(Assumptions!$C$135*Assumptions!$C$140+Hosting!$C$5*Assumptions!$C$140+MAX(0,ROUNDUP($A18/Assumptions!$C$141,0)-1)*Hosting!$C$5) | D18: =C18/$A18 | E18: =MAX(Assumptions!$C$145,ROUNDUP($A18/Assumptions!$C$146,0)) | F18: =(MAX(Assumptions!$C$145,ROUNDUP($A18/Assumptions!$C$146,0))*Assumptions!$C$144+$A18*Hosting!$C$6) | G18: =F18/$A18 | H18: =IF(Assumptions!$C$155=1,(Assumptions!$C$135*Assumptions!$C$140+Hosting!$C$5*Assumptions!$C$140+MAX(0,ROUNDUP($A18/Assumptions!$C$141,0)-1)*Hosting!$C$5),IF(Assumptions!$C$155=2,(MAX(Assumptions!$C$145,ROUNDUP($A18/Assumptions!$C$146,0))*Assumptions!$C$144+$A18*Hosting!$C$6),IF($A18>=Assumptions!$C$156,(MAX(Assumptions!$C$145,ROUNDUP($A18/Assumptions!$C$146,0))*Assumptions!$C$144+$A18*Hosting!$C$6),(Assumptions!$C$135*Assumptions!$C$140+Hosting!$C$5*Assumptions!$C$140+MAX(0,ROUNDUP($A18/Assumptions!$C$141,0)-1)*Hosting!$C$5)))) | I18: =H18/$A18 | J18: =Assumptions!$C$159*(Assumptions!$C$160+MAX(0,$A18*Assumptions!$C$163-Assumptions!$C$161)*Assumptions!$C$162) | K18: =J18/$A18 | L18: =I18+K18

Sheet Forecast
A1: Forecast: 24 months, three scenarios
A2: Tenants ramp to a share of the addressable firms at month 24. Revenue and cost per tenant come from Tiers.
A4: Scenario | B4: Share of firms at month 24 | C4: Addressable firms | D4: Tenants, month 12 | E4: MRR, month 12 | F4: Tenants, month 24 | G4: MRR, month 24 | H4: ARR, month 24 | I4: Gross margin, month 24 | J4: One-time fees, 24 months | K4: Revenue, 24 months
A5: Low | B5: =Assumptions!$C$13 | C5: =Assumptions!$C$12 | D5: =B24 | E5: =G24 | F5: =B36 | G5: =G36 | H5: =H36 | I5: =N36 | J5: =SUM(I13:I36) | K5: =O36
A6: Base | B6: =Assumptions!$C$14 | C6: =Assumptions!$C$12 | D6: =B52 | E6: =G52 | F6: =B64 | G6: =G64 | H6: =H64 | I6: =N64 | J6: =SUM(I41:I64) | K6: =O64
A7: High | B7: =Assumptions!$C$15 | C7: =Assumptions!$C$12 | D7: =B80 | E7: =G80 | F7: =B92 | G7: =G92 | H7: =H92 | I7: =N92 | J7: =SUM(I69:I92) | K7: =O92
A9: Market case is mkt_case on the Assumptions sheet. Gross margin is tool cost only.
A11: Low scenario
A12: Month | B12: Active tenants | C12: New tenants | D12: Platform MRR | E12: Add-on MRR | F12: Overage and resale MRR | G12: Total MRR | H12: ARR run rate | I12: One-time fees | J12: Cost: usage | K12: Cost: hosting, sites and lead lines | L12: Cost: one-time | M12: Gross profit | N12: Gross margin | O12: Cumulative revenue
A13: 1 | B13: =MAX(Assumptions!$C$17,ROUND(Assumptions!$C$12*Assumptions!$C$13*(A13/24)^Assumptions!$C$16,0)) | C13: =MAX(0,B13-Assumptions!$C$17+ROUND(Assumptions!$C$18*Assumptions!$C$17,0)) | D13: =B13*Assumptions!$C$21 | E13: =B13*Tiers!$B$24 | F13: =B13*Tiers!$B$25 | G13: =D13+E13+F13 | H13: =G13*12 | I13: =C13*Tiers!$B$27 | J13: =B13*Tiers!$B$26 | K13: =IF(Assumptions!$C$155=1,(Assumptions!$C$135*Assumptions!$C$140+Hosting!$C$5*Assumptions!$C$140+MAX(0,ROUNDUP(B13/Assumptions!$C$141,0)-1)*Hosting!$C$5),IF(Assumptions!$C$155=2,(MAX(Assumptions!$C$145,ROUNDUP(B13/Assumptions!$C$146,0))*Assumptions!$C$144+B13*Hosting!$C$6),IF(B13>=Assumptions!$C$156,(MAX(Assumptions!$C$145,ROUNDUP(B13/Assumptions!$C$146,0))*Assumptions!$C$144+B13*Hosting!$C$6),(Assumptions!$C$135*Assumptions!$C$140+Hosting!$C$5*Assumptions!$C$140+MAX(0,ROUNDUP(B13/Assumptions!$C$141,0)-1)*Hosting!$C$5))))+Assumptions!$C$159*(Assumptions!$C$160+MAX(0,B13*Assumptions!$C$163-Assumptions!$C$161)*Assumptions!$C$162)+Assumptions!$C$164*Assumptions!$C$165+B13*(Assumptions!$C$168+Assumptions!$C$169) | L13: =C13*Tiers!$B$28 | M13: =G13+I13-J13-K13-L13 | N13: =IF(G13+I13>0,M13/(G13+I13),0) | O13: =G13+I13
A14: 2 | B14: =MAX(Assumptions!$C$17,ROUND(Assumptions!$C$12*Assumptions!$C$13*(A14/24)^Assumptions!$C$16,0)) | C14: =MAX(0,B14-B13+ROUND(Assumptions!$C$18*B13,0)) | D14: =B14*Assumptions!$C$21 | E14: =B14*Tiers!$B$24 | F14: =B14*Tiers!$B$25 | G14: =D14+E14+F14 | H14: =G14*12 | I14: =C14*Tiers!$B$27 | J14: =B14*Tiers!$B$26 | K14: =IF(Assumptions!$C$155=1,(Assumptions!$C$135*Assumptions!$C$140+Hosting!$C$5*Assumptions!$C$140+MAX(0,ROUNDUP(B14/Assumptions!$C$141,0)-1)*Hosting!$C$5),IF(Assumptions!$C$155=2,(MAX(Assumptions!$C$145,ROUNDUP(B14/Assumptions!$C$146,0))*Assumptions!$C$144+B14*Hosting!$C$6),IF(B14>=Assumptions!$C$156,(MAX(Assumptions!$C$145,ROUNDUP(B14/Assumptions!$C$146,0))*Assumptions!$C$144+B14*Hosting!$C$6),(Assumptions!$C$135*Assumptions!$C$140+Hosting!$C$5*Assumptions!$C$140+MAX(0,ROUNDUP(B14/Assumptions!$C$141,0)-1)*Hosting!$C$5))))+Assumptions!$C$159*(Assumptions!$C$160+MAX(0,B14*Assumptions!$C$163-Assumptions!$C$161)*Assumptions!$C$162)+Assumptions!$C$164*Assumptions!$C$165+B14*(Assumptions!$C$168+Assumptions!$C$169) | L14: =C14*Tiers!$B$28 | M14: =G14+I14-J14-K14-L14 | N14: =IF(G14+I14>0,M14/(G14+I14),0) | O14: =O13+G14+I14
A15: 3 | B15: =MAX(Assumptions!$C$17,ROUND(Assumptions!$C$12*Assumptions!$C$13*(A15/24)^Assumptions!$C$16,0)) | C15: =MAX(0,B15-B14+ROUND(Assumptions!$C$18*B14,0)) | D15: =B15*Assumptions!$C$21 | E15: =B15*Tiers!$B$24 | F15: =B15*Tiers!$B$25 | G15: =D15+E15+F15 | H15: =G15*12 | I15: =C15*Tiers!$B$27 | J15: =B15*Tiers!$B$26 | K15: =IF(Assumptions!$C$155=1,(Assumptions!$C$135*Assumptions!$C$140+Hosting!$C$5*Assumptions!$C$140+MAX(0,ROUNDUP(B15/Assumptions!$C$141,0)-1)*Hosting!$C$5),IF(Assumptions!$C$155=2,(MAX(Assumptions!$C$145,ROUNDUP(B15/Assumptions!$C$146,0))*Assumptions!$C$144+B15*Hosting!$C$6),IF(B15>=Assumptions!$C$156,(MAX(Assumptions!$C$145,ROUNDUP(B15/Assumptions!$C$146,0))*Assumptions!$C$144+B15*Hosting!$C$6),(Assumptions!$C$135*Assumptions!$C$140+Hosting!$C$5*Assumptions!$C$140+MAX(0,ROUNDUP(B15/Assumptions!$C$141,0)-1)*Hosting!$C$5))))+Assumptions!$C$159*(Assumptions!$C$160+MAX(0,B15*Assumptions!$C$163-Assumptions!$C$161)*Assumptions!$C$162)+Assumptions!$C$164*Assumptions!$C$165+B15*(Assumptions!$C$168+Assumptions!$C$169) | L15: =C15*Tiers!$B$28 | M15: =G15+I15-J15-K15-L15 | N15: =IF(G15+I15>0,M15/(G15+I15),0) | O15: =O14+G15+I15
A16: 4 | B16: =MAX(Assumptions!$C$17,ROUND(Assumptions!$C$12*Assumptions!$C$13*(A16/24)^Assumptions!$C$16,0)) | C16: =MAX(0,B16-B15+ROUND(Assumptions!$C$18*B15,0)) | D16: =B16*Assumptions!$C$21 | E16: =B16*Tiers!$B$24 | F16: =B16*Tiers!$B$25 | G16: =D16+E16+F16 | H16: =G16*12 | I16: =C16*Tiers!$B$27 | J16: =B16*Tiers!$B$26 | K16: =IF(Assumptions!$C$155=1,(Assumptions!$C$135*Assumptions!$C$140+Hosting!$C$5*Assumptions!$C$140+MAX(0,ROUNDUP(B16/Assumptions!$C$141,0)-1)*Hosting!$C$5),IF(Assumptions!$C$155=2,(MAX(Assumptions!$C$145,ROUNDUP(B16/Assumptions!$C$146,0))*Assumptions!$C$144+B16*Hosting!$C$6),IF(B16>=Assumptions!$C$156,(MAX(Assumptions!$C$145,ROUNDUP(B16/Assumptions!$C$146,0))*Assumptions!$C$144+B16*Hosting!$C$6),(Assumptions!$C$135*Assumptions!$C$140+Hosting!$C$5*Assumptions!$C$140+MAX(0,ROUNDUP(B16/Assumptions!$C$141,0)-1)*Hosting!$C$5))))+Assumptions!$C$159*(Assumptions!$C$160+MAX(0,B16*Assumptions!$C$163-Assumptions!$C$161)*Assumptions!$C$162)+Assumptions!$C$164*Assumptions!$C$165+B16*(Assumptions!$C$168+Assumptions!$C$169) | L16: =C16*Tiers!$B$28 | M16: =G16+I16-J16-K16-L16 | N16: =IF(G16+I16>0,M16/(G16+I16),0) | O16: =O15+G16+I16
